Workbook

Sheet Customer Names
B2: CUSTOMER ID | C2: NAME | D2: NAME LEN | E2: NAME TRIM | F2: NAME TRIM LEN | G2: TITLE | H2: FIRST NAME | I2: LAST NAME
B3: Id1 | C3: Hawks, Ms. Kelly | D3: =LEN(C3) -> 17 | E3: =TRIM(C3) -> Hawks, Ms. Kelly | F3: =LEN(E3) -> 16 | G3: Ms | H3: Kelly | I3: Hawks
B4: Id2 | C4: Lehner, Mr. Matthew D | D4: =LEN(C4) -> 22 | E4: =TRIM(C4) -> Lehner, Mr. Matthew D | F4: =LEN(E4) -> 21 | G4: Mr | H4: Matthew D | I4: Lehner
B5: Id3 | C5: Lu, Mr. Phil | D5: =LEN(C5) -> 13 | E5: =TRIM(C5) -> Lu, Mr. Phil | F5: =LEN(E5) -> 12 | G5: Mr | H5: Phil | I5: Lu
B6: Id4 | C6: Osborne, Ms. Kelsey | D6: =LEN(C6) -> 20 | E6: =TRIM(C6) -> Osborne, Ms. Kelsey | F6: =LEN(E6) -> 19 | G6: Ms | H6: Kelsey | I6: Osborne
B7: Id5 | C7: Kadala, Ms. Kristyn | D7: =LEN(C7) -> 20 | E7: =TRIM(C7) -> Kadala, Ms. Kristyn | F7: =LEN(E7) -> 19 | G7: Ms | H7: Kristyn | I7: Kadala
B8: Id6 | C8: Baker, Mr. Russell B. | D8: =LEN(C8) -> 22 | E8: =TRIM(C8) -> Baker, Mr. Russell B. | F8: =LEN(E8) -> 21 | G8: Mr | H8: Russell B | I8: Baker
B9: Id7 | C9: Macpherson, Mr. Scott | D9: =LEN(C9) -> 22 | E9: =TRIM(C9) -> Macpherson, Mr. Scott | F9: =LEN(E9) -> 21 | G9: Mr | H9: Scott | I9: Macpherson
B10: Id8 | C10: Hallman, Mr. Stephen | D10: =LEN(C10) -> 21 | E10: =TRIM(C10) -> Hallman, Mr. Stephen | F10: =LEN(E10) -> 20 | G10: Mr | H10: Stephen | I10: Hallman
B11: Id9 | C11: Moran, Mr. Patrick R. | D11: =LEN(C11) -> 22 | E11: =TRIM(C11) -> Moran, Mr. Patrick R. | F11: =LEN(E11) -> 21 | G11: Mr | H11: Patrick R | I11: Moran
B12: Id10 | C12: Benner, Ms. Brooke N. | D12: =LEN(C12) -> 22 | E12: =TRIM(C12) -> Benner, Ms. Brooke N. | F12: =LEN(E12) -> 21 | G12: Ms | H12: Brooke N | I12: Benner
B13: Id11 | C13: Fierro Vargas, Ms. Paola Andrea | D13: =LEN(C13) -> 32 | E13: =TRIM(C13) -> Fierro Vargas, Ms. Paola Andrea | F13: =LEN(E13) -> 31 | G13: Ms | H13: Paola Andrea | I13: Fierro Vargas
B14: Id12 | C14: Franz, Mr. David | D14: =LEN(C14) -> 17 | E14: =TRIM(C14) -> Franz, Mr. David | F14: =LEN(E14) -> 16 | G14: Mr | H14: David | I14: Franz
... B2337: Id2335 | C2337: German, Mr. Aaron K | D2337: =LEN(C2337) -> 20 | E2337: =TRIM(C2337) -> German, Mr. Aaron K | F2337: =LEN(E2337) -> 19 | G2337: Mr | H2337: Aaron K | I2337: German

Sheet Medical Examination
B2: CUSTOMER ID | C2: BMI | D2: WEIGHT STATUS | E2: HBA1C | F2: DIABETES STATUS | G2: HEART ISSUES | H2: ANY TRANSPLANTS | I2: CANCER HISTORY | J2: NUMBER OF MAJOR SURGERIES | K2: SMOKER | L2: SMOKER IMPUTED | M2: NUMBER OF MAJOR SURGERIES IMPUTED
B3: Id1 | C3: 47.41 | D3: =IF(C3<18.5,"Underweight", IF(AND(C3>=18.5,C3<=24.9),"Healthy Weight", IF(AND(C3>=25,C3<=29.9),"Overweight", IF(C3>=30,"Obesity")))) -> Obesity | E3: 7.47 | F3: =IF(E3<5.7,"Normal",IF(AND(E3>=5.7,E3<=6.4),"Prediabetes",IF(E3>=6.5,"Diabetes"))) -> Diabetes | G3: No | H3: No | I3: No | J3: No major surgery | K3: Yes | L3: =IF($K$3:$K$2337="?","No",K3) -> Yes | M3: =IF(J3="No major surgery", 0,J3) -> 0
B4: Id2 | C4: 30.36 | D4: =IF(C4<18.5,"Underweight", IF(AND(C4>=18.5,C4<=24.9),"Healthy Weight", IF(AND(C4>=25,C4<=29.9),"Overweight", IF(C4>=30,"Obesity")))) -> Obesity | E4: 5.77 | F4: =IF(E4<5.7,"Normal",IF(AND(E4>=5.7,E4<=6.4),"Prediabetes",IF(E4>=6.5,"Diabetes"))) -> Prediabetes | G4: No | H4: No | I4: No | J4: No major surgery | K4: Yes | L4: =IF($K$3:$K$2337="?","No",K4) -> Yes | M4: =IF(J4="No major surgery", 0,J4) -> 0
B5: Id3 | C5: 34.485 | D5: =IF(C5<18.5,"Underweight", IF(AND(C5>=18.5,C5<=24.9),"Healthy Weight", IF(AND(C5>=25,C5<=29.9),"Overweight", IF(C5>=30,"Obesity")))) -> Obesity | E5: 11.87 | F5: =IF(E5<5.7,"Normal",IF(AND(E5>=5.7,E5<=6.4),"Prediabetes",IF(E5>=6.5,"Diabetes"))) -> Diabetes | G5: Yes | H5: No | I5: No | J5: 2 | K5: Yes | L5: =IF($K$3:$K$2337="?","No",K5) -> Yes | M5: =IF(J5="No major surgery", 0,J5) -> 2
B6: Id4 | C6: 38.095 | D6: =IF(C6<18.5,"Underweight", IF(AND(C6>=18.5,C6<=24.9),"Healthy Weight", IF(AND(C6>=25,C6<=29.9),"Overweight", IF(C6>=30,"Obesity")))) -> Obesity | E6: 6.05 | F6: =IF(E6<5.7,"Normal",IF(AND(E6>=5.7,E6<=6.4),"Prediabetes",IF(E6>=6.5,"Diabetes"))) -> Prediabetes | G6: No | H6: No | I6: No | J6: No major surgery | K6: Yes | L6: =IF($K$3:$K$2337="?","No",K6) -> Yes | M6: =IF(J6="No major surgery", 0,J6) -> 0
B7: Id5 | C7: 35.53 | D7: =IF(C7<18.5,"Underweight", IF(AND(C7>=18.5,C7<=24.9),"Healthy Weight", IF(AND(C7>=25,C7<=29.9),"Overweight", IF(C7>=30,"Obesity")))) -> Obesity | E7: 5.45 | F7: =IF(E7<5.7,"Normal",IF(AND(E7>=5.7,E7<=6.4),"Prediabetes",IF(E7>=6.5,"Diabetes"))) -> Normal | G7: No | H7: No | I7: No | J7: No major surgery | K7: Yes | L7: =IF($K$3:$K$2337="?","No",K7) -> Yes | M7: =IF(J7="No major surgery", 0,J7) -> 0
B8: Id6 | C8: 32.8 | D8: =IF(C8<18.5,"Underweight", IF(AND(C8>=18.5,C8<=24.9),"Healthy Weight", IF(AND(C8>=25,C8<=29.9),"Overweight", IF(C8>=30,"Obesity")))) -> Obesity | E8: 6.59 | F8: =IF(E8<5.7,"Normal",IF(AND(E8>=5.7,E8<=6.4),"Prediabetes",IF(E8>=6.5,"Diabetes"))) -> Diabetes | G8: No | H8: No | I8: No | J8: No major surgery | K8: Yes | L8: =IF($K$3:$K$2337="?","No",K8) -> Yes | M8: =IF(J8="No major surgery", 0,J8) -> 0
B9: Id7 | C9: 36.4 | D9: =IF(C9<18.5,"Underweight", IF(AND(C9>=18.5,C9<=24.9),"Healthy Weight", IF(AND(C9>=25,C9<=29.9),"Overweight", IF(C9>=30,"Obesity")))) -> Obesity | E9: 6.07 | F9: =IF(E9<5.7,"Normal",IF(AND(E9>=5.7,E9<=6.4),"Prediabetes",IF(E9>=6.5,"Diabetes"))) -> Prediabetes | G9: No | H9: No | I9: No | J9: No major surgery | K9: Yes | L9: =IF($K$3:$K$2337="?","No",K9) -> Yes | M9: =IF(J9="No major surgery", 0,J9) -> 0
B10: Id8 | C10: 36.96 | D10: =IF(C10<18.5,"Underweight", IF(AND(C10>=18.5,C10<=24.9),"Healthy Weight", IF(AND(C10>=25,C10<=29.9),"Overweight", IF(C10>=30,"Obesity")))) -> Obesity | E10: 7.93 | F10: =IF(E10<5.7,"Normal",IF(AND(E10>=5.7,E10<=6.4),"Prediabetes",IF(E10>=6.5,"Diabetes"))) -> Diabetes | G10: No | H10: No | I10: No | J10: 3 | K10: Yes | L10: =IF($K$3:$K$2337="?","No",K10) -> Yes | M10: =IF(J10="No major surgery", 0,J10) -> 3
B11: Id9 | C11: 41.14 | D11: =IF(C11<18.5,"Underweight", IF(AND(C11>=18.5,C11<=24.9),"Healthy Weight", IF(AND(C11>=25,C11<=29.9),"Overweight", IF(C11>=30,"Obesity")))) -> Obesity | E11: 9.58 | F11: =IF(E11<5.7,"Normal",IF(AND(E11>=5.7,E11<=6.4),"Prediabetes",IF(E11>=6.5,"Diabetes"))) -> Diabetes | G11: Yes | H11: No | I11: Yes | J11: 1 | K11: Yes | L11: =IF($K$3:$K$2337="?","No",K11) -> Yes | M11: =IF(J11="No major surgery", 0,J11) -> 1
B12: Id10 | C12: 38.06 | D12: =IF(C12<18.5,"Underweight", IF(AND(C12>=18.5,C12<=24.9),"Healthy Weight", IF(AND(C12>=25,C12<=29.9),"Overweight", IF(C12>=30,"Obesity")))) -> Obesity | E12: 10.79 | F12: =IF(E12<5.7,"Normal",IF(AND(E12>=5.7,E12<=6.4),"Prediabetes",IF(E12>=6.5,"Diabetes"))) -> Diabetes | G12: No | H12: No | I12: No | J12: No major surgery | K12: Yes | L12: =IF($K$3:$K$2337="?","No",K12) -> Yes | M12: =IF(J12="No major surgery", 0,J12) -> 0
B13: Id11 | C13: 37.7 | D13: =IF(C13<18.5,"Underweight", IF(AND(C13>=18.5,C13<=24.9),"Healthy Weight", IF(AND(C13>=25,C13<=29.9),"Overweight", IF(C13>=30,"Obesity")))) -> Obesity | E13: 5.96 | F13: =IF(E13<5.7,"Normal",IF(AND(E13>=5.7,E13<=6.4),"Prediabetes",IF(E13>=6.5,"Diabetes"))) -> Prediabetes | G13: Yes | H13: No | I13: No | J13: 2 | K13: Yes | L13: =IF($K$3:$K$2337="?","No",K13) -> Yes | M13: =IF(J13="No major surgery", 0,J13) -> 2
B14: Id12 | C14: 42.13 | D14: =IF(C14<18.5,"Underweight", IF(AND(C14>=18.5,C14<=24.9),"Healthy Weight", IF(AND(C14>=25,C14<=29.9),"Overweight", IF(C14>=30,"Obesity")))) -> Obesity | E14: 11.9 | F14: =IF(E14<5.7,"Normal",IF(AND(E14>=5.7,E14<=6.4),"Prediabetes",IF(E14>=6.5,"Diabetes"))) -> Diabetes | G14: No | H14: No | I14: No | J14: No major surgery | K14: Yes | L14: =IF($K$3:$K$2337="?","No",K14) -> Yes | M14: =IF(J14="No major surgery", 0,J14) -> 0
B15: Id13 | C15: 40.92 | D15: =IF(C15<18.5,"Underweight", IF(AND(C15>=18.5,C15<=24.9),"Healthy Weight", IF(AND(C15>=25,C15<=29.9),"Overweight", IF(C15>=30,"Obesity")))) -> Obesity | E15: 8.41 | F15: =IF(E15<5.7,"Normal",IF(AND(E15>=5.7,E15<=6.4),"Prediabetes",IF(E15>=6.5,"Diabetes"))) -> Diabetes | G15: No | H15: No | I15: No | J15: No major surgery | K15: Yes | L15: =IF($K$3:$K$2337="?","No",K15) -> Yes | M15: =IF(J15="No major surgery", 0,J15) -> 0
B16: Id14 | C16: 40.565 | D16: =IF(C16<18.5,"Underweight", IF(AND(C16>=18.5,C16<=24.9),"Healthy Weight", IF(AND(C16>=25,C16<=29.9),"Overweight", IF(C16>=30,"Obesity")))) -> Obesity | E16: 7.02 | F16: =IF(E16<5.7,"Normal",IF(AND(E16>=5.7,E16<=6.4),"Prediabetes",IF(E16>=6.5,"Diabetes"))) -> Diabetes | G16: No | H16: No | I16: No | J16: No major surgery | K16: Yes | L16: =IF($K$3:$K$2337="?","No",K16) -> Yes | M16: =IF(J16="No major surgery", 0,J16) -> 0
B17: Id15 | C17: 36.385 | D17: =IF(C17<18.5,"Underweight", IF(AND(C17>=18.5,C17<=24.9),"Healthy Weight", IF(AND(C17>=25,C17<=29.9),"Overweight", IF(C17>=30,"Obesity")))) -> Obesity | E17: 7.59 | F17: =IF(E17<5.7,"Normal",IF(AND(E17>=5.7,E17<=6.4),"Prediabetes",IF(E17>=6.5,"Diabetes"))) -> Diabetes | G17: Yes | H17: No | I17: No | J17: 2 | K17: Yes | L17: =IF($K$3:$K$2337="?","No",K17) -> Yes | M17: =IF(J17="No major surgery", 0,J17) -> 2
B18: Id16 | C18: 39.9 | D18: =IF(C18<18.5,"Underweight", IF(AND(C18>=18.5,C18<=24.9),"Healthy Weight", IF(AND(C18>=25,C18<=29.9),"Overweight", IF(C18>=30,"Obesity")))) -> Obesity | E18: 11.32 | F18: =IF(E18<5.7,"Normal",IF(AND(E18>=5.7,E18<=6.4),"Prediabetes",IF(E18>=6.5,"Diabetes"))) -> Diabetes | G18: No | H18: No | I18: No | J18: No major surgery | K18: Yes | L18: =IF($K$3:$K$2337="?","No",K18) -> Yes | M18: =IF(J18="No major surgery", 0,J18) -> 0
B19: Id17 | C19: 33.8 | D19: =IF(C19<18.5,"Underweight", IF(AND(C19>=18.5,C19<=24.9),"Healthy Weight", IF(AND(C19>=25,C19<=29.9),"Overweight", IF(C19>=30,"Obesity")))) -> Obesity | E19: 7.67 | F19: =IF(E19<5.7,"Normal",IF(AND(E19>=5.7,E19<=6.4),"Prediabetes",IF(E19>=6.5,"Diabetes"))) -> Diabetes | G19: No | H19: No | I19: No | J19: 3 | K19: Yes | L19: =IF($K$3:$K$2337="?","No",K19) -> Yes | M19: =IF(J19="No major surgery", 0,J19) -> 3
B20: Id18 | C20: 36.765 | D20: =IF(C20<18.5,"Underweight", IF(AND(C20>=18.5,C20<=24.9),"Healthy Weight", IF(AND(C20>=25,C20<=29.9),"Overweight", IF(C20>=30,"Obesity")))) -> Obesity | E20: 7.29 | F20: =IF(E20<5.7,"Normal",IF(AND(E20>=5.7,E20<=6.4),"Prediabetes",IF(E20>=6.5,"Diabetes"))) -> Diabetes | G20: Yes | H20: No | I20: Yes | J20: 1 | K20: Yes | L20: =IF($K$3:$K$2337="?","No",K20) -> Yes | M20: =IF(J20="No major surgery", 0,J20) -> 1
B21: Id19 | C21: 36.955 | D21: =IF(C21<18.5,"Underweight", IF(AND(C21>=18.5,C21<=24.9),"Healthy Weight", IF(AND(C21>=25,C21<=29.9),"Overweight", IF(C21>=30,"Obesity")))) -> Obesity | E21: 4.72 | F21: =IF(E21<5.7,"Normal",IF(AND(E21>=5.7,E21<=6.4),"Prediabetes",IF(E21>=6.5,"Diabetes"))) -> Normal | G21: Yes | H21: No | I21: No | J21: 1 | K21: Yes | L21: =IF($K$3:$K$2337="?","No",K21) -> Yes | M21: =IF(J21="No major surgery", 0,J21) -> 1
B22: Id20 | C22: 42.9 | D22: =IF(C22<18.5,"Underweight", IF(AND(C22>=18.5,C22<=24.9),"Healthy Weight", IF(AND(C22>=25,C22<=29.9),"Overweight", IF(C22>=30,"Obesity")))) -> Obesity | E22: 11.41 | F22: =IF(E22<5.7,"Normal",IF(AND(E22>=5.7,E22<=6.4),"Prediabetes",IF(E22>=6.5,"Diabetes"))) -> Diabetes | G22: No | H22: No | I22: No | J22: No major surgery | K22: Yes | L22: =IF($K$3:$K$2337="?","No",K22) -> Yes | M22: =IF(J22="No major surgery", 0,J22) -> 0
B23: Id21 | C23: 36.3 | D23: =IF(C23<18.5,"Underweight", IF(AND(C23>=18.5,C23<=24.9),"Healthy Weight", IF(AND(C23>=25,C23<=29.9),"Overweight", IF(C23>=30,"Obesity")))) -> Obesity | E23: 11.5 | F23: =IF(E23<5.7,"Normal",IF(AND(E23>=5.7,E23<=6.4),"Prediabetes",IF(E23>=6.5,"Diabetes"))) -> Diabetes | G23: Yes | H23: No | I23: No | J23: 2 | K23: Yes | L23: =IF($K$3:$K$2337="?","No",K23) -> Yes | M23: =IF(J23="No major surgery", 0,J23) -> 2
B24: Id22 | C24: 32.2 | D24: =IF(C24<18.5,"Underweight", IF(AND(C24>=18.5,C24<=24.9),"Healthy Weight", IF(AND(C24>=25,C24<=29.9),"Overweight", IF(C24>=30,"Obesity")))) -> Obesity | E24: 6.22 | F24: =IF(E24<5.7,"Normal",IF(AND(E24>=5.7,E24<=6.4),"Prediabetes",IF(E24>=6.5,"Diabetes"))) -> Prediabetes | G24: Yes | H24: No | I24: No | J24: 2 | K24: Yes | L24: =IF($K$3:$K$2337="?","No",K24) -> Yes | M24: =IF(J24="No major surgery", 0,J24) -> 2
B25: Id23 | C25: 31.3 | D25: =IF(C25<18.5,"Underweight", IF(AND(C25>=18.5,C25<=24.9),"Healthy Weight", IF(AND(C25>=25,C25<=29.9),"Overweight", IF(C25>=30,"Obesity")))) -> Obesity | E25: 11.38 | F25: =IF(E25<5.7,"Normal",IF(AND(E25>=5.7,E25<=6.4),"Prediabetes",IF(E25>=6.5,"Diabetes"))) -> Diabetes | G25: No | H25: No | I25: No | J25: 3 | K25: Yes | L25: =IF($K$3:$K$2337="?","No",K25) -> Yes | M25: =IF(J25="No major surgery", 0,J25) -> 3
B26: Id24 | C26: 41.8 | D26: =IF(C26<18.5,"Underweight", IF(AND(C26>=18.5,C26<=24.9),"Healthy Weight", IF(AND(C26>=25,C26<=29.9),"Overweight", IF(C26>=30,"Obesity")))) -> Obesity | E26: 7.89 | F26: =IF(E26<5.7,"Normal",IF(AND(E26>=5.7,E26<=6.4),"Prediabetes",IF(E26>=6.5,"Diabetes"))) -> Diabetes | G26: Yes | H26: No | I26: No | J26: 2 | K26: Yes | L26: =IF($K$3:$K$2337="?","No",K26) -> Yes | M26: =IF(J26="No major surgery", 0,J26) -> 2
B27: Id25 | C27: 35.09 | D27: =IF(C27<18.5,"Underweight", IF(AND(C27>=18.5,C27<=24.9),"Healthy Weight", IF(AND(C27>=25,C27<=29.9),"Overweight", IF(C27>=30,"Obesity")))) -> Obesity | E27: 4.38 | F27: =IF(E27<5.7,"Normal",IF(AND(E27>=5.7,E27<=6.4),"Prediabetes",IF(E27>=6.5,"Diabetes"))) -> Normal | G27: Yes | H27: No | I27: No | J27: 2 | K27: Yes | L27: =IF($K$3:$K$2337="?","No",K27) -> Yes | M27: =IF(J27="No major surgery", 0,J27) -> 2
B28: Id26 | C28: 33.88 | D28: =IF(C28<18.5,"Underweight", IF(AND(C28>=18.5,C28<=24.9),"Healthy Weight", IF(AND(C28>=25,C28<=29.9),"Overweight", IF(C28>=30,"Obesity")))) -> Obesity | E28: 7.01 | F28: =IF(E28<5.7,"Normal",IF(AND(E28>=5.7,E28<=6.4),"Prediabetes",IF(E28>=6.5,"Diabetes"))) -> Diabetes | G28: No | H28: No | I28: No | J28: 3 | K28: Yes | L28: =IF($K$3:$K$2337="?","No",K28) -> Yes | M28: =IF(J28="No major surgery", 0,J28) -> 3
B29: Id27 | C29: 30.875 | D29: =IF(C29<18.5,"Underweight", IF(AND(C29>=18.5,C29<=24.9),"Healthy Weight", IF(AND(C29>=25,C29<=29.9),"Overweight", IF(C29>=30,"Obesity")))) -> Obesity | E29: 11.88 | F29: =IF(E29<5.7,"Normal",IF(AND(E29>=5.7,E29<=6.4),"Prediabetes",IF(E29>=6.5,"Diabetes"))) -> Diabetes | G29: No | H29: No | I29: No | J29: No major surgery | K29: Yes | L29: =IF($K$3:$K$2337="?","No",K29) -> Yes | M29: =IF(J29="No major surgery", 0,J29) -> 0
B30: Id28 | C30: 36.86 | D30: =IF(C30<18.5,"Underweight", IF(AND(C30>=18.5,C30<=24.9),"Healthy Weight", IF(AND(C30>=25,C30<=29.9),"Overweight", IF(C30>=30,"Obesity")))) -> Obesity | E30: 5.19 | F30: =IF(E30<5.7,"Normal",IF(AND(E30>=5.7,E30<=6.4),"Prediabetes",IF(E30>=6.5,"Diabetes"))) -> Normal | G30: Yes | H30: No | I30: Yes | J30: 1 | K30: Yes | L30: =IF($K$3:$K$2337="?","No",K30) -> Yes | M30: =IF(J30="No major surgery", 0,J30) -> 1
B31: Id29 | C31: 35.86 | D31: =IF(C31<18.5,"Underweight", IF(AND(C31>=18.5,C31<=24.9),"Healthy Weight", IF(AND(C31>=25,C31<=29.9),"Overweight", IF(C31>=30,"Obesity")))) -> Obesity | E31: 6.74 | F31: =IF(E31<5.7,"Normal",IF(AND(E31>=5.7,E31<=6.4),"Prediabetes",IF(E31>=6.5,"Diabetes"))) -> Diabetes | G31: Yes | H31: No | I31: No | J31: 2 | K31: Yes | L31: =IF($K$3:$K$2337="?","No",K31) -> Yes | M31: =IF(J31="No major surgery", 0,J31) -> 2
B32: Id30 | C32: 37.05 | D32: =IF(C32<18.5,"Underweight", IF(AND(C32>=18.5,C32<=24.9),"Healthy Weight", IF(AND(C32>=25,C32<=29.9),"Overweight", IF(C32>=30,"Obesity")))) -> Obesity | E32: 8.44 | F32: =IF(E32<5.7,"Normal",IF(AND(E32>=5.7,E32<=6.4),"Prediabetes",IF(E32>=6.5,"Diabetes"))) -> Diabetes | G32: No | H32: No | I32: No | J32: No major surgery | K32: Yes | L32: =IF($K$3:$K$2337="?","No",K32) -> Yes | M32: =IF(J32="No major surgery", 0,J32) -> 0
B33: Id31 | C33: 43.89 | D33: =IF(C33<18.5,"Underweight", IF(AND(C33>=18.5,C33<=24.9),"Healthy Weight", IF(AND(C33>=25,C33<=29.9),"Overweight", IF(C33>=30,"Obesity")))) -> Obesity | E33: 8.71 | F33: =IF(E33<5.7,"Normal",IF(AND(E33>=5.7,E33<=6.4),"Prediabetes",IF(E33>=6.5,"Diabetes"))) -> Diabetes | G33: No | H33: No | I33: No | J33: No major surgery | K33: Yes | L33: =IF($K$3:$K$2337="?","No",K33) -> Yes | M33: =IF(J33="No major surgery", 0,J33) -> 0
B34: Id32 | C34: 42.35 | D34: =IF(C34<18.5,"Underweight", IF(AND(C34>=18.5,C34<=24.9),"Healthy Weight", IF(AND(C34>=25,C34<=29.9),"Overweight", IF(C34>=30,"Obesity")))) -> Obesity | E34: 5.08 | F34: =IF(E34<5.7,"Normal",IF(AND(E34>=5.7,E34<=6.4),"Prediabetes",IF(E34>=6.5,"Diabetes"))) -> Normal | G34: Yes | H34: No | I34: No | J34: No major surgery | K34: Yes | L34: =IF($K$3:$K$2337="?","No",K34) -> Yes | M34: =IF(J34="No major surgery", 0,J34) -> 0
B35: Id33 | C35: 31.35 | D35: =IF(C35<18.5,"Underweight", IF(AND(C35>=18.5,C35<=24.9),"Healthy Weight", IF(AND(C35>=25,C35<=29.9),"Overweight", IF(C35>=30,"Obesity")))) -> Obesity | E35: 6.86 | F35: =IF(E35<5.7,"Normal",IF(AND(E35>=5.7,E35<=6.4),"Prediabetes",IF(E35>=6.5,"Diabetes"))) -> Diabetes | G35: No | H35: No | I35: No | J35: No major surgery | K35: Yes | L35: =IF($K$3:$K$2337="?","No",K35) -> Yes | M35: =IF(J35="No major surgery", 0,J35) -> 0
B36: Id34 | C36: 47.6 | D36: =IF(C36<18.5,"Underweight", IF(AND(C36>=18.5,C36<=24.9),"Healthy Weight", IF(AND(C36>=25,C36<=29.9),"Overweight", IF(C36>=30,"Obesity")))) -> Obesity | E36: 5.95 | F36: =IF(E36<5.7,"Normal",IF(AND(E36>=5.7,E36<=6.4),"Prediabetes",IF(E36>=6.5,"Diabetes"))) -> Prediabetes | G36: Yes | H36: No | I36: No | J36: No major surgery | K36: Yes | L36: =IF($K$3:$K$2337="?","No",K36) -> Yes | M36: =IF(J36="No major surgery", 0,J36) -> 0
B37: Id35 | C37: 46.2 | D37: =IF(C37<18.5,"Underweight", IF(AND(C37>=18.5,C37<=24.9),"Healthy Weight", IF(AND(C37>=25,C37<=29.9),"Overweight", IF(C37>=30,"Obesity")))) -> Obesity | E37: 6.09 | F37: =IF(E37<5.7,"Normal",IF(AND(E37>=5.7,E37<=6.4),"Prediabetes",IF(E37>=6.5,"Diabetes"))) -> Prediabetes | G37: No | H37: No | I37: Yes | J37: 1 | K37: Yes | L37: =IF($K$3:$K$2337="?","No",K37) -> Yes | M37: =IF(J37="No major surgery", 0,J37) -> 1
B38: Id36 | C38: 32.015 | D38: =IF(C38<18.5,"Underweight", IF(AND(C38>=18.5,C38<=24.9),"Healthy Weight", IF(AND(C38>=25,C38<=29.9),"Overweight", IF(C38>=30,"Obesity")))) -> Obesity | E38: 11.75 | F38: =IF(E38<5.7,"Normal",IF(AND(E38>=5.7,E38<=6.4),"Prediabetes",IF(E38>=6.5,"Diabetes"))) -> Diabetes | G38: No | H38: No | I38: No | J38: No major surgery | K38: Yes | L38: =IF($K$3:$K$2337="?","No",K38) -> Yes | M38: =IF(J38="No major surgery", 0,J38) -> 0
B39: Id37 | C39: 40.565 | D39: =IF(C39<18.5,"Underweight", IF(AND(C39>=18.5,C39<=24.9),"Healthy Weight", IF(AND(C39>=25,C39<=29.9),"Overweight", IF(C39>=30,"Obesity")))) -> Obesity | E39: 7.37 | F39: =IF(E39<5.7,"Normal",IF(AND(E39>=5.7,E39<=6.4),"Prediabetes",IF(E39>=6.5,"Diabetes"))) -> Diabetes | G39: No | H39: No | I39: No | J39: No major surgery | K39: Yes | L39: =IF($K$3:$K$2337="?","No",K39) -> Yes | M39: =IF(J39="No major surgery", 0,J39) -> 0
B40: Id38 | C40: 32.45 | D40: =IF(C40<18.5,"Underweight", IF(AND(C40>=18.5,C40<=24.9),"Healthy Weight", IF(AND(C40>=25,C40<=29.9),"Overweight", IF(C40>=30,"Obesity")))) -> Obesity | E40: 11.91 | F40: =IF(E40<5.7,"Normal",IF(AND(E40>=5.7,E40<=6.4),"Prediabetes",IF(E40>=6.5,"Diabetes"))) -> Diabetes | G40: No | H40: No | I40: No | J40: No major surgery | K40: Yes | L40: =IF($K$3:$K$2337="?","No",K40) -> Yes | M40: =IF(J40="No major surgery", 0,J40) -> 0
B41: Id39 | C41: 34.96 | D41: =IF(C41<18.5,"Underweight", IF(AND(C41>=18.5,C41<=24.9),"Healthy Weight", IF(AND(C41>=25,C41<=29.9),"Overweight", IF(C41>=30,"Obesity")))) -> Obesity | E41: 6.52 | F41: =IF(E41<5.7,"Normal",IF(AND(E41>=5.7,E41<=6.4),"Prediabetes",IF(E41>=6.5,"Diabetes"))) -> Diabetes | G41: No | H41: No | I41: No | J41: No major surgery | K41: Yes | L41: =IF($K$3:$K$2337="?","No",K41) -> Yes | M41: =IF(J41="No major surgery", 0,J41) -> 0
...

Sheet Hospitalisation Details
B2: CUSTOMER ID | C2: YEAR | D2: MONTH | E2: DATE | F2: CHILDREN | G2: CHARGES | H2: HOSPITAL TIER | I2: CITY TIER | J2: STATE ID | K2: MONTH IMPUTED | L2: YEAR IMPUTED | M2: HOSPITAL TIER IMPUTED | N2: CITY TIER IMPUTED | O2: DATE OF BIRTH | P2: AGE
B3: Id2335 | C3: 1992 | D3: Jul | E3: 9 | F3: 0 | G3: 563.84 | H3: tier - 2 | I3: tier - 3 | J3: R1013 | K3: =IF(D3="?", "Sep",D3) -> Jul | L3: =IF(C3="?","1983",C3) -> 1992 | M3: =IF(H3="?", "tier - 2",H3) -> tier - 2 | N3: =IF(I3="?", "tier - 2", I3) -> tier - 3 | O3: =CONCATENATE(E3&"-"&K3&"-"&L3) -> 9-Jul-1992 | P3: =2023-L3 -> 31
B4: Id2334 | C4: 1992 | D4: Nov | E4: 30 | F4: 0 | G4: 570.62 | H4: tier - 2 | I4: tier - 1 | J4: R1013 | K4: =IF(D4="?", "Sep",D4) -> Nov | L4: =IF(C4="?","1983",C4) -> 1992 | M4: =IF(H4="?", "tier - 2",H4) -> tier - 2 | N4: =IF(I4="?", "tier - 2", I4) -> tier - 1 | O4: =CONCATENATE(E4&"-"&K4&"-"&L4) -> 30-Nov-1992 | P4: =2023-L4 -> 31
B5: Id2333 | C5: 1993 | D5: Jun | E5: 30 | F5: 0 | G5: 600 | H5: tier - 2 | I5: tier - 1 | J5: R1013 | K5: =IF(D5="?", "Sep",D5) -> Jun | L5: =IF(C5="?","1983",C5) -> 1993 | M5: =IF(H5="?", "tier - 2",H5) -> tier - 2 | N5: =IF(I5="?", "tier - 2", I5) -> tier - 1 | O5: =CONCATENATE(E5&"-"&K5&"-"&L5) -> 30-Jun-1993 | P5: =2023-L5 -> 30
B6: Id2332 | C6: 1992 | D6: Sep | E6: 13 | F6: 0 | G6: 604.54 | H6: tier - 3 | I6: tier - 3 | J6: R1013 | K6: =IF(D6="?", "Sep",D6) -> Sep | L6: =IF(C6="?","1983",C6) -> 1992 | M6: =IF(H6="?", "tier - 2",H6) -> tier - 3 | N6: =IF(I6="?", "tier - 2", I6) -> tier - 3 | O6: =CONCATENATE(E6&"-"&K6&"-"&L6) -> 13-Sep-1992 | P6: =2023-L6 -> 31
B7: Id2331 | C7: 1998 | D7: Jul | E7: 27 | F7: 0 | G7: 637.26 | H7: tier - 3 | I7: tier - 3 | J7: R1013 | K7: =IF(D7="?", "Sep",D7) -> Jul | L7: =IF(C7="?","1983",C7) -> 1998 | M7: =IF(H7="?", "tier - 2",H7) -> tier - 3 | N7: =IF(I7="?", "tier - 2", I7) -> tier - 3 | O7: =CONCATENATE(E7&"-"&K7&"-"&L7) -> 27-Jul-1998 | P7: =2023-L7 -> 25
B8: Id2330 | C8: 2001 | D8: Nov | E8: 20 | F8: 0 | G8: 646.14 | H8: tier - 3 | I8: tier - 3 | J8: R1012 | K8: =IF(D8="?", "Sep",D8) -> Nov | L8: =IF(C8="?","1983",C8) -> 2001 | M8: =IF(H8="?", "tier - 2",H8) -> tier - 3 | N8: =IF(I8="?", "tier - 2", I8) -> tier - 3 | O8: =CONCATENATE(E8&"-"&K8&"-"&L8) -> 20-Nov-2001 | P8: =2023-L8 -> 22
B9: Id2329 | C9: 1993 | D9: Jun | E9: 1 | F9: 0 | G9: 650 | H9: tier - 3 | I9: tier - 3 | J9: R1013 | K9: =IF(D9="?", "Sep",D9) -> Jun | L9: =IF(C9="?","1983",C9) -> 1993 | M9: =IF(H9="?", "tier - 2",H9) -> tier - 3 | N9: =IF(I9="?", "tier - 2", I9) -> tier - 3 | O9: =CONCATENATE(E9&"-"&K9&"-"&L9) -> 1-Jun-1993 | P9: =2023-L9 -> 30
B10: Id2328 | C10: 1995 | D10: Jul | E10: 4 | F10: 0 | G10: 650 | H10: tier - 3 | I10: tier - 3 | J10: R1013 | K10: =IF(D10="?", "Sep",D10) -> Jul | L10: =IF(C10="?","1983",C10) -> 1995 | M10: =IF(H10="?", "tier - 2",H10) -> tier - 3 | N10: =IF(I10="?", "tier - 2", I10) -> tier - 3 | O10: =CONCATENATE(E10&"-"&K10&"-"&L10) -> 4-Jul-1995 | P10: =2023-L10 -> 28
B11: Id2327 | C11: 2002 | D11: Nov | E11: 29 | F11: 0 | G11: 668 | H11: tier - 3 | I11: tier - 2 | J11: R1012 | K11: =IF(D11="?", "Sep",D11) -> Nov | L11: =IF(C11="?","1983",C11) -> 2002 | M11: =IF(H11="?", "tier - 2",H11) -> tier - 3 | N11: =IF(I11="?", "tier - 2", I11) -> tier - 2 | O11: =CONCATENATE(E11&"-"&K11&"-"&L11) -> 29-Nov-2002 | P11: =2023-L11 -> 21
B12: Id2326 | C12: 1997 | D12: Nov | E12: 9 | F12: 0 | G12: 670 | H12: tier - 3 | I12: tier - 3 | J12: R1013 | K12: =IF(D12="?", "Sep",D12) -> Nov | L12: =IF(C12="?","1983",C12) -> 1997 | M12: =IF(H12="?", "tier - 2",H12) -> tier - 3 | N12: =IF(I12="?", "tier - 2", I12) -> tier - 3 | O12: =CONCATENATE(E12&"-"&K12&"-"&L12) -> 9-Nov-1997 | P12: =2023-L12 -> 26
B13: Id2325 | C13: 2001 | D13: Sep | E13: 12 | F13: 0 | G13: 687.54 | H13: tier - 3 | I13: tier - 2 | J13: R1013 | K13: =IF(D13="?", "Sep",D13) -> Sep | L13: =IF(C13="?","1983",C13) -> 2001 | M13: =IF(H13="?", "tier - 2",H13) -> tier - 3 | N13: =IF(I13="?", "tier - 2", I13) -> tier - 2 | O13: =CONCATENATE(E13&"-"&K13&"-"&L13) -> 12-Sep-2001 | P13: =2023-L13 -> 22
B14: Id2324 | C14: 1999 | D14: Dec | E14: 26 | F14: 0 | G14: 700 | H14: ? | I14: tier - 3 | J14: R1013 | K14: =IF(D14="?", "Sep",D14) -> Dec | L14: =IF(C14="?","1983",C14) -> 1999 | M14: =IF(H14="?", "tier - 2",H14) -> tier - 2 | N14: =IF(I14="?", "tier - 2", I14) -> tier - 3 | O14: =CONCATENATE(E14&"-"&K14&"-"&L14) -> 26-Dec-1999 | P14: =2023-L14 -> 24
... B1049: Id1290 | C1049: 1977 | D1049: Jul | E1049: 26 | F1049: 2 | G1049: 8527.53 | H1049: tier - 2 | I1049: tier - 2 | J1049: R1013 | K1049: =IF(D1049="?", "Sep",D1049) -> Jul | L1049: =IF(C1049="?","1983",C1049) -> 1977 | M1049: =IF(H1049="?", "tier - 2",H1049) -> tier - 2 | N1049: =IF(I1049="?", "tier - 2", I1049) -> tier - 2 | O1049: =CONCATENATE(E1049&"-"&K1049&"-"&L1049) -> 26-Jul-1977 | P1049: =2023-L1049 -> 46
B1050: Id1289 | C1050: ? | D1050: Jul | E1050: 24 | F1050: 0 | G1050: 8534.67 | H1050: tier - 2 | I1050: tier - 3 | J1050: R1024 | K1050: =IF(D1050="?", "Sep",D1050) -> Jul | L1050: =IF(C1050="?","1983",C1050) -> 1983 | M1050: =IF(H1050="?", "tier - 2",H1050) -> tier - 2 | N1050: =IF(I1050="?", "tier - 2", I1050) -> tier - 3 | O1050: =CONCATENATE(E1050&"-"&K1050&"-"&L1050) -> 24-Jul-1983 | P1050: =2023-L1050 -> 40
B1051: Id1288 | C1051: 1981 | D1051: Dec | E1051: 27 | F1051: 3 | G1051: 8538.29 | H1051: tier - 2 | I1051: tier - 3 | J1051: R1024 | K1051: =IF(D1051="?", "Sep",D1051) -> Dec | L1051: =IF(C1051="?","1983",C1051) -> 1981 | M1051: =IF(H1051="?", "tier - 2",H1051) -> tier - 2 | N1051: =IF(I1051="?", "tier - 2", I1051) -> tier - 3 | O1051: =CONCATENATE(E1051&"-"&K1051&"-"&L1051) -> 27-Dec-1981 | P1051: =2023-L1051 -> 42
B1052: Id1287 | C1052: 1975 | D1052: Nov | E1052: 6 | F1052: 1 | G1052: 8539.67 | H1052: tier - 2 | I1052: tier - 3 | J1052: R1011 | K1052: =IF(D1052="?", "Sep",D1052) -> Nov | L1052: =IF(C1052="?","1983",C1052) -> 1975 | M1052: =IF(H1052="?", "tier - 2",H1052) -> tier - 2 | N1052: =IF(I1052="?", "tier - 2", I1052) -> tier - 3 | O1052: =CONCATENATE(E1052&"-"&K1052&"-"&L1052) -> 6-Nov-1975 | P1052: =2023-L1052 -> 48
B1053: Id1286 | C1053: ? | D1053: Dec | E1053: 12 | F1053: 1 | G1053: 8547.69 | H1053: tier - 2 | I1053: tier - 1 | J1053: R1013 | K1053: =IF(D1053="?", "Sep",D1053) -> Dec | L1053: =IF(C1053="?","1983",C1053) -> 1983 | M1053: =IF(H1053="?", "tier - 2",H1053) -> tier - 2 | N1053: =IF(I1053="?", "tier - 2", I1053) -> tier - 1 | O1053: =CONCATENATE(E1053&"-"&K1053&"-"&L1053) -> 12-Dec-1983 | P1053: =2023-L1053 -> 40
B1054: Id1285 | C1054: 1975 | D1054: Aug | E1054: 6 | F1054: 1 | G1054: 8551.35 | H1054: tier - 2 | I1054: tier - 2 | J1054: R1011 | K1054: =IF(D1054="?", "Sep",D1054) -> Aug | L1054: =IF(C1054="?","1983",C1054) -> 1975 | M1054: =IF(H1054="?", "tier - 2",H1054) -> tier - 2 | N1054: =IF(I1054="?", "tier - 2", I1054) -> tier - 2 | O1054: =CONCATENATE(E1054&"-"&K1054&"-"&L1054) -> 6-Aug-1975 | P1054: =2023-L1054 -> 48
B1055: Id1284 | C1055: 1975 | D1055: Aug | E1055: 21 | F1055: 1 | G1055: 8556.91 | H1055: tier - 2 | I1055: tier - 1 | J1055: R1011 | K1055: =IF(D1055="?", "Sep",D1055) -> Aug | L1055: =IF(C1055="?","1983",C1055) -> 1975 | M1055: =IF(H1055="?", "tier - 2",H1055) -> tier - 2 | N1055: =IF(I1055="?", "tier - 2", I1055) -> tier - 1 | O1055: =CONCATENATE(E1055&"-"&K1055&"-"&L1055) -> 21-Aug-1975 | P1055: =2023-L1055 -> 48
B1056: Id1283 | C1056: 1988 | D1056: Sep | E1056: 21 | F1056: 3 | G1056: 8567.25 | H1056: tier - 2 | I1056: tier - 1 | J1056: R1012 | K1056: =IF(D1056="?", "Sep",D1056) -> Sep | L1056: =IF(C1056="?","1983",C1056) -> 1988 | M1056: =IF(H1056="?", "tier - 2",H1056) -> tier - 2 | N1056: =IF(I1056="?", "tier - 2", I1056) -> tier - 1 | O1056: =CONCATENATE(E1056&"-"&K1056&"-"&L1056) -> 21-Sep-1988 | P1056: =2023-L1056 -> 35
B1057: Id1282 | C1057: 1975 | D1057: Sep | E1057: 26 | F1057: 1 | G1057: 8569.86 | H1057: tier - 2 | I1057: tier - 3 | J1057: R1013 | K1057: =IF(D1057="?", "Sep",D1057) -> Sep | L1057: =IF(C1057="?","1983",C1057) -> 1975 | M1057: =IF(H1057="?", "tier - 2",H1057) -> tier - 2 | N1057: =IF(I1057="?", "tier - 2", I1057) -> tier - 3 | O1057: =CONCATENATE(E1057&"-"&K1057&"-"&L1057) -> 26-Sep-1975 | P1057: =2023-L1057 -> 48
B1058: Id1281 | C1058: 1982 | D1058: Dec | E1058: 6 | F1058: 3 | G1058: 8572.04 | H1058: tier - 2 | I1058: tier - 2 | J1058: R1021 | K1058: =IF(D1058="?", "Sep",D1058) -> Dec | L1058: =IF(C1058="?","1983",C1058) -> 1982 | M1058: =IF(H1058="?", "tier - 2",H1058) -> tier - 2 | N1058: =IF(I1058="?", "tier - 2", I1058) -> tier - 2 | O1058: =CONCATENATE(E1058&"-"&K1058&"-"&L1058) -> 6-Dec-1982 | P1058: =2023-L1058 -> 41
B1059: Id1280 | C1059: 1987 | D1059: Nov | E1059: 11 | F1059: 3 | G1059: 8573.3 | H1059: tier - 2 | I1059: tier - 2 | J1059: R1021 | K1059: =IF(D1059="?", "Sep",D1059) -> Nov | L1059: =IF(C1059="?","1983",C1059) -> 1987 | M1059: =IF(H1059="?", "tier - 2",H1059) -> tier - 2 | N1059: =IF(I1059="?", "tier - 2", I1059) -> tier - 2 | O1059: =CONCATENATE(E1059&"-"&K1059&"-"&L1059) -> 11-Nov-1987 | P1059: =2023-L1059 -> 36
B1060: Id1279 | C1060: 1983 | D1060: Dec | E1060: 30 | F1060: 5 | G1060: 8582.3 | H1060: tier - 2 | I1060: tier - 1 | J1060: R1013 | K1060: =IF(D1060="?", "Sep",D1060) -> Dec | L1060: =IF(C1060="?","1983",C1060) -> 1983 | M1060: =IF(H1060="?", "tier - 2",H1060) -> tier - 2 | N1060: =IF(I1060="?", "tier - 2", I1060) -> tier - 1 | O1060: =CONCATENATE(E1060&"-"&K1060&"-"&L1060) -> 30-Dec-1983 | P1060: =2023-L1060 -> 40
B1061: Id1278 | C1061: 1983 | D1061: Jul | E1061: 25 | F1061: 5 | G1061: 8596.83 | H1061: tier - 2 | I1061: tier - 3 | J1061: R1013 | K1061: =IF(D1061="?", "Sep",D1061) -> Jul | L1061: =IF(C1061="?","1983",C1061) -> 1983 | M1061: =IF(H1061="?", "tier - 2",H1061) -> tier - 2 | N1061: =IF(I1061="?", "tier - 2", I1061) -> tier - 3 | O1061: =CONCATENATE(E1061&"-"&K1061&"-"&L1061) -> 25-Jul-1983 | P1061: =2023-L1061 -> 40
B1062: Id1277 | C1062: 1973 | D1062: Jul | E1062: 11 | F1062: 0 | G1062: 8601.33 | H1062: tier - 2 | I1062: tier - 1 | J1062: R1013 | K1062: =IF(D1062="?", "Sep",D1062) -> Jul | L1062: =IF(C1062="?","1983",C1062) -> 1973 | M1062: =IF(H1062="?", "tier - 2",H1062) -> tier - 2 | N1062: =IF(I1062="?", "tier - 2", I1062) -> tier - 1 | O1062: =CONCATENATE(E1062&"-"&K1062&"-"&L1062) -> 11-Jul-1973 | P1062: =2023-L1062 -> 50
B1063: Id1276 | C1063: 1977 | D1063: Sep | E1063: 24 | F1063: 2 | G1063: 8603.82 | H1063: tier - 2 | I1063: tier - 1 | J1063: R1019 | K1063: =IF(D1063="?", "Sep",D1063) -> Sep | L1063: =IF(C1063="?","1983",C1063) -> 1977 | M1063: =IF(H1063="?", "tier - 2",H1063) -> tier - 2 | N1063: =IF(I1063="?", "tier - 2", I1063) -> tier - 1 | O1063: =CONCATENATE(E1063&"-"&K1063&"-"&L1063) -> 24-Sep-1977 | P1063: =2023-L1063 -> 46
B1064: Id1275 | C1064: 1977 | D1064: Nov | E1064: 12 | F1064: 2 | G1064: 8604.48 | H1064: tier - 3 | I1064: tier - 2 | J1064: R1016 | K1064: =IF(D1064="?", "Sep",D1064) -> Nov | L1064: =IF(C1064="?","1983",C1064) -> 1977 | M1064: =IF(H1064="?", "tier - 2",H1064) -> tier - 3 | N1064: =IF(I1064="?", "tier - 2", I1064) -> tier - 2 | O1064: =CONCATENATE(E1064&"-"&K1064&"-"&L1064) -> 12-Nov-1977 | P1064: =2023-L1064 -> 46
B1065: Id1274 | C1065: 1977 | D1065: Oct | E1065: 15 | F1065: 3 | G1065: 8605.36 | H1065: tier - 2 | I1065: tier - 2 | J1065: R1013 | K1065: =IF(D1065="?", "Sep",D1065) -> Oct | L1065: =IF(C1065="?","1983",C1065) -> 1977 | M1065: =IF(H1065="?", "tier - 2",H1065) -> tier - 2 | N1065: =IF(I1065="?", "tier - 2", I1065) -> tier - 2 | O1065: =CONCATENATE(E1065&"-"&K1065&"-"&L1065) -> 15-Oct-1977 | P1065: =2023-L1065 -> 46
... B2340: Id1 | C2340: 1968 | D2340: Oct | E2340: 12 | F2340: 0 | G2340: 63770.43 | H2340: tier - 1 | I2340: tier - 3 | J2340: R1013 | K2340: =IF(D2340="?", "Sep",D2340) -> Oct | L2340: =IF(C2340="?","1983",C2340) -> 1968 | M2340: =IF(H2340="?", "tier - 2",H2340) -> tier - 1 | N2340: =IF(I2340="?", "tier - 2", I2340) -> tier - 3 | O2340: =CONCATENATE(E2340&"-"&K2340&"-"&L2340) -> 12-Oct-1968 | P2340: =2023-L2340 -> 55

Sheet Data Exploration
B2: DATA EXPLORATION
B3: Customer Names Table: | C3: SOLUTIONS
B4: 1. Are there any duplicate Customer IDs in the dataset? If yes, how many? | C4: No - duplicate Customer IDs in the dataset
B5: 2. How many customers are included in the dataset? | C5: =COUNTA('Customer Names'!B3:B2337) -> 2335
B7: Medical Examination Table: | C7: SOLUTIONS
B8: 1. How many customers have a history of cancer? | C8: =COUNTIF('Medical Examination'!I3:I2337,'Medical Examination'!I11) -> 391
B9: 2. Identify the customer(s) with the highest BMI. | C9: =MAX('Medical Examination'!C3:C2337) -> 55.05 | D9: Customer ID - ID464
B10: 3. How many customers have Diabetes? | C10: =COUNTIF('Medical Examination'!F3:F2337,'Medical Examination'!F3) -> 784
B11: 4. How many obese customers have heart issues? | C11: =COUNTIFS('Medical Examination'!D3:D2337,'Medical Examination'!D3,'Medical Examination'!G3:G2337,'Medical Examination'!G5) -> 490
B12: 5. What is the total number of major surgeries performed on customers? | C12: =SUM('Medical Examination'!J3:J2337) -> 1579
B13: 6. Calculate the percentage of customers who have undergone any transplants. | C13: =ROUND(D13/E13*100,0) -> 6 | D13: =COUNTIF('Medical Examination'!H3:H2337, 'Medical Examination'!H43) -> 144 | E13: =COUNTA('Medical Examination'!H3:H2337) -> 2335
B14: 7. Find the average HBA1C value of customers who are smokers. | C14: =ROUND(AVERAGEIF('Medical Examination'!K2:K2337,'Medical Examination'!K3,'Medical Examination'!E3:E2337),0) -> 7
B15: 8. How many customers with heart issues have done a transplant? | C15: =COUNTIFS('Medical Examination'!G3:G2337,'Medical Examination'!G5,'Medical Examination'!H3:H2337,'Medical Examination'!H43) -> 19
B16: 9. What is the average BMI of customers who have done more than 2 major surgeries? | C16: =ROUND(AVERAGEIF('Medical Examination'!J3:J2337,">2",'Medical Examination'!C3:C2337),0) -> 33
B18: Hospitalization details Table: | C18: SOLUTIONS
B19: 1. Calculate all the Summary statistics for the 'charges' column.
B20: Count | C20: =COUNT('Hospitalisation Details'!$G$3:$G$2340) -> 2338
B21: Sum | C21: =SUM('Hospitalisation Details'!$G$3:$G$2340) -> 31648783
B22: Average | C22: =AVERAGE('Hospitalisation Details'!$G$3:$G$2340) -> 13536.691
B23: Median | C23: =MEDIAN('Hospitalisation Details'!$G$3:$G$2340) -> 9632.725
B24: Mode | C24: =MODE('Hospitalisation Details'!$G$3:$G$2340) -> 650
B25: S.D - Sample | C25: =_xlfn.STDEV.S('Hospitalisation Details'!$G$3:$G$2340) -> 11902.535
B26: S.D - Population | C26: =_xlfn.STDEV.P('Hospitalisation Details'!$G$3:$G$2340) -> 11899.989
B27: Min | C27: =MIN('Hospitalisation Details'!$G$3:$G$2340) -> 563.84
B28: Max | C28: =MAX('Hospitalisation Details'!$G$3:$G$2340) -> 63770.43
B30: 2. Which is the median age and the most common age in the dataset?
B31: Median | C31: =MEDIAN('Hospitalisation Details'!$P$3:$P$2340) -> 40
B32: Mode | C32: =MODE('Hospitalisation Details'!$P$3:$P$2340) -> 19
B34: 3. Find the average hospitalization charges for customers who are more than 50 years old. | C34: =AVERAGEIF('Hospitalisation Details'!P3:P2340,">50",'Hospitalisation Details'!G3:G2340) -> 17710.133
B35: 4. Compare the total charges across different hospital tiers. | C35: Sum | D35: Average
B36: hospital tier - 1 | C36: =SUMIF('Hospitalisation Details'!$H$3:$H$2340,'Hospitalisation Details'!$H393,'Hospitalisation Details'!$G$3:$G$2340) -> 9193579.5 | D36: =AVERAGEIF('Hospitalisation Details'!$H$3:$H$2340,'Hospitalisation Details'!$H393,'Hospitalisation Details'!$G$3:$G$2340) -> 30142.884
B37: hospital tier - 2 | C37: =SUMIF('Hospitalisation Details'!$H$3:$H$2340,'Hospitalisation Details'!$H3,'Hospitalisation Details'!$G$3:$G$2340) -> 15896014 | D37: =AVERAGEIF('Hospitalisation Details'!$H$3:$H$2340,'Hospitalisation Details'!$H3,'Hospitalisation Details'!$G$3:$G$2340) -> 11880.429
B38: hospital tier - 3 | C38: =SUMIF('Hospitalisation Details'!$H$3:$H$2340,'Hospitalisation Details'!$H6,'Hospitalisation Details'!$G$3:$G$2340) -> 6558489.6 | D38: =AVERAGEIF('Hospitalisation Details'!$H$3:$H$2340,'Hospitalisation Details'!$H6,'Hospitalisation Details'!$G$3:$G$2340) -> 9450.2733
B40: 5. Which city tier has the highest average hospitalization charges? | C40: Average
B41: city tier - 1 | C41: =AVERAGEIF('Hospitalisation Details'!$I$3:$I$2340,'Hospitalisation Details'!$I4,'Hospitalisation Details'!$G$3:$G$2340) -> 13035.097
B42: city tier - 2 | C42: =AVERAGEIF('Hospitalisation Details'!$I$3:$I$2340,'Hospitalisation Details'!$I11,'Hospitalisation Details'!$G$3:$G$2340) -> 13470.52
B43: city tier - 3 | C43: =AVERAGEIF('Hospitalisation Details'!$I$3:$I$2340,'Hospitalisation Details'!$I3,'Hospitalisation Details'!$G$3:$G$2340) -> 14082.56
B45: 6. Calculate the average charges for people who have more than 2 children. | C45: =AVERAGEIF('Hospitalisation Details'!F3:F2340,">2",'Hospitalisation Details'!G3:G2340) -> 14217.52
B46: 7. Find the integer average number of children of customers who are less than 40 years old. | C46: =ROUND(AVERAGEIF('Hospitalisation Details'!P3:P2340,"<40",'Hospitalisation Details'!F3:F2340),0) -> 1

Sheet Healthcare
T2: HEALTHCARE - VLOOKUP
B3: CUSTOMER ID | C3: FIRST NAME | D3: BMI | E3: WEIGHT STATUS | F3: HBA1C | G3: DIABETES STATUS | H3: HEART ISSUES | I3: ANY TRANSPLANTS | J3: CANCER HISTORY | K3: NUMBER OF MAJOR SURGERIES | L3: SMOKER | M3: DATE OF BIRTH | N3: AGE | O3: CHARGES | P3: HOSPITAL TIER | Q3: CITY TIER | R3: STATE ID | T3: CUSTOMER ID | U3: FIRST NAME | V3: BMI | W3: WEIGHT STATUS | X3: HBA1C | Y3: DIABETES STATUS | Z3: HEART ISSUES | AA3: ANY TRANSPLANTS | AB3: CANCER HISTORY | AC3: NUMBER OF MAJOR SURGERIES | AD3: SMOKER | AE3: DATE OF BIRTH | AF3: AGE | AG3: CHARGES | AH3: HOSPITAL TIER | AI3: CITY TIER | AJ3: STATE ID
B4: Id1 | C4: Kelly | D4: 47.41 | E4: =IF(D4<18.5,"Underweight", IF(AND(D4>=18.5,D4<=24.9),"Healthy Weight", IF(AND(D4>=25,D4<=29.9),"Overweight", IF(D4>=30,"Obesity")))) -> Obesity | F4: 7.47 | G4: =IF(F4<5.7,"Normal",IF(AND(F4>=5.7,F4<=6.4),"Prediabetes",IF(F4>=6.5,"Diabetes"))) -> Diabetes | H4: No | I4: No | J4: No | K4: No major surgery | L4: Yes | M4: 9-Jul-1992 | N4: 31 | O4: 563.84 | P4: tier - 2 | Q4: tier - 3 | R4: R1013 | T4: Id1 | U4: =VLOOKUP($T$4,$B$3:$R$2338,2,FALSE) -> Kelly | V4: =VLOOKUP(T4,$B$3:$R$2338,3,FALSE) -> 47.41 | W4: =VLOOKUP(T4,$B$3:$R$2338,4,FALSE) -> Obesity | X4: =VLOOKUP(T4,$B$3:$R$2338,5,FALSE) -> 7.47 | Y4: =VLOOKUP(T4,$B$3:$R$2338,6,0) -> Diabetes | Z4: =VLOOKUP(T4,$B$3:$R$2338,7,0) -> No | AA4: =VLOOKUP(T4,$B$3:$R$2338,8,0) -> No | AB4: =VLOOKUP(T4,$B$3:$R$2338,9,0) -> No | AC4: =VLOOKUP(T4,$B$3:$R$2338,10,0) -> No major surgery | AD4: =VLOOKUP(T4,$B$3:$R$2338,11,0) -> Yes | AE4: =VLOOKUP(T4,$B$3:$R$2338,12,0) -> 9-Jul-1992 | AF4: =VLOOKUP(T4,$B$3:$R$2338,13,0) -> 31 | AG4: =VLOOKUP(T4,$B$3:$R$2338,14,0) -> 563.84 | AH4: =VLOOKUP(T4,$B$3:$R$2338,15,0) -> tier - 2 | AI4: =VLOOKUP(T4,B3:R2338,16,0) -> tier - 3 | AJ4: =VLOOKUP(T4,$B$3:$R$2338,17,0) -> R1013
B5: Id2 | C5: Matthew D | D5: 30.36 | E5: =IF(D5<18.5,"Underweight", IF(AND(D5>=18.5,D5<=24.9),"Healthy Weight", IF(AND(D5>=25,D5<=29.9),"Overweight", IF(D5>=30,"Obesity")))) -> Obesity | F5: 5.77 | G5: =IF(F5<5.7,"Normal",IF(AND(F5>=5.7,F5<=6.4),"Prediabetes",IF(F5>=6.5,"Diabetes"))) -> Prediabetes | H5: No | I5: No | J5: No | K5: No major surgery | L5: Yes | M5: 30-Nov-1992 | N5: 31 | O5: 570.62 | P5: tier - 2 | Q5: tier - 1 | R5: R1013 | T5: Id2 | U5: =VLOOKUP(T5,$B$3:$R$2338,2,FALSE) -> Matthew D | V5: =VLOOKUP(T5,$B$3:$R$2338,3,FALSE) -> 30.36 | W5: =VLOOKUP(T5,$B$3:$R$2338,4,FALSE) -> Obesity | X5: =VLOOKUP(T5,$B$3:$R$2338,5,FALSE) -> 5.77 | Y5: =VLOOKUP(T5,$B$3:$R$2338,6,0) -> Prediabetes | Z5: =VLOOKUP(T5,$B$3:$R$2338,7,0) -> No | AA5: =VLOOKUP(T5,$B$3:$R$2338,8,0) -> No | AB5: =VLOOKUP(T5,$B$3:$R$2338,9,0) -> No | AC5: =VLOOKUP(T5,$B$3:$R$2338,10,0) -> No major surgery | AD5: =VLOOKUP(T5,$B$3:$R$2338,11,0) -> Yes | AE5: =VLOOKUP(T5,$B$3:$R$2338,12,0) -> 30-Nov-1992 | AF5: =VLOOKUP(T5,$B$3:$R$2338,13,0) -> 31 | AG5: =VLOOKUP(T5,$B$3:$R$2338,14,0) -> 570.62 | AH5: =VLOOKUP(T5,$B$3:$R$2338,15,0) -> tier - 2 | AI5: =VLOOKUP(T5,B4:R2339,16,0) -> tier - 1 | AJ5: =VLOOKUP(T5,$B$3:$R$2338,17,0) -> R1013
B6: Id3 | C6: Phil | D6: 34.485 | E6: =IF(D6<18.5,"Underweight", IF(AND(D6>=18.5,D6<=24.9),"Healthy Weight", IF(AND(D6>=25,D6<=29.9),"Overweight", IF(D6>=30,"Obesity")))) -> Obesity | F6: 11.87 | G6: =IF(F6<5.7,"Normal",IF(AND(F6>=5.7,F6<=6.4),"Prediabetes",IF(F6>=6.5,"Diabetes"))) -> Diabetes | H6: Yes | I6: No | J6: No | K6: 2 | L6: Yes | M6: 30-Jun-1993 | N6: 30 | O6: 600 | P6: tier - 2 | Q6: tier - 1 | R6: R1013 | T6: Id3 | U6: =VLOOKUP(T6,$B$3:$R$2338,2,FALSE) -> Phil | V6: =VLOOKUP(T6,$B$3:$R$2338,3,FALSE) -> 34.485 | W6: =VLOOKUP(T6,$B$3:$R$2338,4,FALSE) -> Obesity | X6: =VLOOKUP(T6,$B$3:$R$2338,5,FALSE) -> 11.87 | Y6: =VLOOKUP(T6,$B$3:$R$2338,6,0) -> Diabetes | Z6: =VLOOKUP(T6,$B$3:$R$2338,7,0) -> Yes | AA6: =VLOOKUP(T6,$B$3:$R$2338,8,0) -> No | AB6: =VLOOKUP(T6,$B$3:$R$2338,9,0) -> No | AC6: =VLOOKUP(T6,$B$3:$R$2338,10,0) -> 2 | AD6: =VLOOKUP(T6,$B$3:$R$2338,11,0) -> Yes | AE6: =VLOOKUP(T6,$B$3:$R$2338,12,0) -> 30-Jun-1993 | AF6: =VLOOKUP(T6,$B$3:$R$2338,13,0) -> 30 | AG6: =VLOOKUP(T6,$B$3:$R$2338,14,0) -> 600 | AH6: =VLOOKUP(T6,$B$3:$R$2338,15,0) -> tier - 2 | AI6: =VLOOKUP(T6,B5:R2340,16,0) -> tier - 1 | AJ6: =VLOOKUP(T6,$B$3:$R$2338,17,0) -> R1013
B7: Id4 | C7: Kelsey | D7: 38.095 | E7: =IF(D7<18.5,"Underweight", IF(AND(D7>=18.5,D7<=24.9),"Healthy Weight", IF(AND(D7>=25,D7<=29.9),"Overweight", IF(D7>=30,"Obesity")))) -> Obesity | F7: 6.05 | G7: =IF(F7<5.7,"Normal",IF(AND(F7>=5.7,F7<=6.4),"Prediabetes",IF(F7>=6.5,"Diabetes"))) -> Prediabetes | H7: No | I7: No | J7: No | K7: No major surgery | L7: Yes | M7: 13-Sep-1992 | N7: 31 | O7: 604.54 | P7: tier - 3 | Q7: tier - 3 | R7: R1013 | T7: Id4 | U7: =VLOOKUP(T7,$B$3:$R$2338,2,FALSE) -> Kelsey | V7: =VLOOKUP(T7,$B$3:$R$2338,3,FALSE) -> 38.095 | W7: =VLOOKUP(T7,$B$3:$R$2338,4,FALSE) -> Obesity | X7: =VLOOKUP(T7,$B$3:$R$2338,5,FALSE) -> 6.05 | Y7: =VLOOKUP(T7,$B$3:$R$2338,6,0) -> Prediabetes | Z7: =VLOOKUP(T7,$B$3:$R$2338,7,0) -> No | AA7: =VLOOKUP(T7,$B$3:$R$2338,8,0) -> No | AB7: =VLOOKUP(T7,$B$3:$R$2338,9,0) -> No | AC7: =VLOOKUP(T7,$B$3:$R$2338,10,0) -> No major surgery | AD7: =VLOOKUP(T7,$B$3:$R$2338,11,0) -> Yes | AE7: =VLOOKUP(T7,$B$3:$R$2338,12,0) -> 13-Sep-1992 | AF7: =VLOOKUP(T7,$B$3:$R$2338,13,0) -> 31 | AG7: =VLOOKUP(T7,$B$3:$R$2338,14,0) -> 604.54 | AH7: =VLOOKUP(T7,$B$3:$R$2338,15,0) -> tier - 3 | AI7: =VLOOKUP(T7,B6:R2341,16,0) -> tier - 3 | AJ7: =VLOOKUP(T7,$B$3:$R$2338,17,0) -> R1013
B8: Id5 | C8: Kristyn | D8: 35.53 | E8: =IF(D8<18.5,"Underweight", IF(AND(D8>=18.5,D8<=24.9),"Healthy Weight", IF(AND(D8>=25,D8<=29.9),"Overweight", IF(D8>=30,"Obesity")))) -> Obesity | F8: 5.45 | G8: =IF(F8<5.7,"Normal",IF(AND(F8>=5.7,F8<=6.4),"Prediabetes",IF(F8>=6.5,"Diabetes"))) -> Normal | H8: No | I8: No | J8: No | K8: No major surgery | L8: Yes | M8: 27-Jul-1998 | N8: 25 | O8: 637.26 | P8: tier - 3 | Q8: tier - 3 | R8: R1013 | T8: Id5 | U8: =VLOOKUP(T8,$B$3:$R$2338,2,FALSE) -> Kristyn | V8: =VLOOKUP(T8,$B$3:$R$2338,3,FALSE) -> 35.53 | W8: =VLOOKUP(T8,$B$3:$R$2338,4,FALSE) -> Obesity | X8: =VLOOKUP(T8,$B$3:$R$2338,5,FALSE) -> 5.45 | Y8: =VLOOKUP(T8,$B$3:$R$2338,6,0) -> Normal | Z8: =VLOOKUP(T8,$B$3:$R$2338,7,0) -> No | AA8: =VLOOKUP(T8,$B$3:$R$2338,8,0) -> No | AB8: =VLOOKUP(T8,$B$3:$R$2338,9,0) -> No | AC8: =VLOOKUP(T8,$B$3:$R$2338,10,0) -> No major surgery | AD8: =VLOOKUP(T8,$B$3:$R$2338,11,0) -> Yes | AE8: =VLOOKUP(T8,$B$3:$R$2338,12,0) -> 27-Jul-1998 | AF8: =VLOOKUP(T8,$B$3:$R$2338,13,0) -> 25 | AG8: =VLOOKUP(T8,$B$3:$R$2338,14,0) -> 637.26 | AH8: =VLOOKUP(T8,$B$3:$R$2338,15,0) -> tier - 3 | AI8: =VLOOKUP(T8,B7:R2342,16,0) -> tier - 3 | AJ8: =VLOOKUP(T8,$B$3:$R$2338,17,0) -> R1013
B9: Id6 | C9: Russell B | D9: 32.8 | E9: =IF(D9<18.5,"Underweight", IF(AND(D9>=18.5,D9<=24.9),"Healthy Weight", IF(AND(D9>=25,D9<=29.9),"Overweight", IF(D9>=30,"Obesity")))) -> Obesity | F9: 6.59 | G9: =IF(F9<5.7,"Normal",IF(AND(F9>=5.7,F9<=6.4),"Prediabetes",IF(F9>=6.5,"Diabetes"))) -> Diabetes | H9: No | I9: No | J9: No | K9: No major surgery | L9: Yes | M9: 20-Nov-2001 | N9: 22 | O9: 646.14 | P9: tier - 3 | Q9: tier - 3 | R9: R1012 | T9: Id6 | U9: =VLOOKUP(T9,$B$3:$R$2338,2,FALSE) -> Russell B | V9: =VLOOKUP(T9,$B$3:$R$2338,3,FALSE) -> 32.8 | W9: =VLOOKUP(T9,$B$3:$R$2338,4,FALSE) -> Obesity | X9: =VLOOKUP(T9,$B$3:$R$2338,5,FALSE) -> 6.59 | Y9: =VLOOKUP(T9,$B$3:$R$2338,6,0) -> Diabetes | Z9: =VLOOKUP(T9,$B$3:$R$2338,7,0) -> No | AA9: =VLOOKUP(T9,$B$3:$R$2338,8,0) -> No | AB9: =VLOOKUP(T9,$B$3:$R$2338,9,0) -> No | AC9: =VLOOKUP(T9,$B$3:$R$2338,10,0) -> No major surgery | AD9: =VLOOKUP(T9,$B$3:$R$2338,11,0) -> Yes | AE9: =VLOOKUP(T9,$B$3:$R$2338,12,0) -> 20-Nov-2001 | AF9: =VLOOKUP(T9,$B$3:$R$2338,13,0) -> 22 | AG9: =VLOOKUP(T9,$B$3:$R$2338,14,0) -> 646.14 | AH9: =VLOOKUP(T9,$B$3:$R$2338,15,0) -> tier - 3 | AI9: =VLOOKUP(T9,B8:R2343,16,0) -> tier - 3 | AJ9: =VLOOKUP(T9,$B$3:$R$2338,17,0) -> R1012
B10: Id7 | C10: Scott | D10: 36.4 | E10: =IF(D10<18.5,"Underweight", IF(AND(D10>=18.5,D10<=24.9),"Healthy Weight", IF(AND(D10>=25,D10<=29.9),"Overweight", IF(D10>=30,"Obesity")))) -> Obesity | F10: 6.07 | G10: =IF(F10<5.7,"Normal",IF(AND(F10>=5.7,F10<=6.4),"Prediabetes",IF(F10>=6.5,"Diabetes"))) -> Prediabetes | H10: No | I10: No | J10: No | K10: No major surgery | L10: Yes | M10: 1-Jun-1993 | N10: 30 | O10: 650 | P10: tier - 3 | Q10: tier - 3 | R10: R1013 | T10: Id7 | U10: =VLOOKUP(T10,$B$3:$R$2338,2,FALSE) -> Scott | V10: =VLOOKUP(T10,$B$3:$R$2338,3,FALSE) -> 36.4 | W10: =VLOOKUP(T10,$B$3:$R$2338,4,FALSE) -> Obesity | X10: =VLOOKUP(T10,$B$3:$R$2338,5,FALSE) -> 6.07 | Y10: =VLOOKUP(T10,$B$3:$R$2338,6,0) -> Prediabetes | Z10: =VLOOKUP(T10,$B$3:$R$2338,7,0) -> No | AA10: =VLOOKUP(T10,$B$3:$R$2338,8,0) -> No | AB10: =VLOOKUP(T10,$B$3:$R$2338,9,0) -> No | AC10: =VLOOKUP(T10,$B$3:$R$2338,10,0) -> No major surgery | AD10: =VLOOKUP(T10,$B$3:$R$2338,11,0) -> Yes | AE10: =VLOOKUP(T10,$B$3:$R$2338,12,0) -> 1-Jun-1993 | AF10: =VLOOKUP(T10,$B$3:$R$2338,13,0) -> 30 | AG10: =VLOOKUP(T10,$B$3:$R$2338,14,0) -> 650 | AH10: =VLOOKUP(T10,$B$3:$R$2338,15,0) -> tier - 3 | AI10: =VLOOKUP(T10,B9:R2344,16,0) -> tier - 3 | AJ10: =VLOOKUP(T10,$B$3:$R$2338,17,0) -> R1013
B11: Id8 | C11: Stephen | D11: 36.96 | E11: =IF(D11<18.5,"Underweight", IF(AND(D11>=18.5,D11<=24.9),"Healthy Weight", IF(AND(D11>=25,D11<=29.9),"Overweight", IF(D11>=30,"Obesity")))) -> Obesity | F11: 7.93 | G11: =IF(F11<5.7,"Normal",IF(AND(F11>=5.7,F11<=6.4),"Prediabetes",IF(F11>=6.5,"Diabetes"))) -> Diabetes | H11: No | I11: No | J11: No | K11: 3 | L11: Yes | M11: 4-Jul-1995 | N11: 28 | O11: 650 | P11: tier - 3 | Q11: tier - 3 | R11: R1013 | T11: Id8 | U11: =VLOOKUP(T11,$B$3:$R$2338,2,FALSE) -> Stephen | V11: =VLOOKUP(T11,$B$3:$R$2338,3,FALSE) -> 36.96 | W11: =VLOOKUP(T11,$B$3:$R$2338,4,FALSE) -> Obesity | X11: =VLOOKUP(T11,$B$3:$R$2338,5,FALSE) -> 7.93 | Y11: =VLOOKUP(T11,$B$3:$R$2338,6,0) -> Diabetes | Z11: =VLOOKUP(T11,$B$3:$R$2338,7,0) -> No | AA11: =VLOOKUP(T11,$B$3:$R$2338,8,0) -> No | AB11: =VLOOKUP(T11,$B$3:$R$2338,9,0) -> No | AC11: =VLOOKUP(T11,$B$3:$R$2338,10,0) -> 3 | AD11: =VLOOKUP(T11,$B$3:$R$2338,11,0) -> Yes | AE11: =VLOOKUP(T11,$B$3:$R$2338,12,0) -> 4-Jul-1995 | AF11: =VLOOKUP(T11,$B$3:$R$2338,13,0) -> 28 | AG11: =VLOOKUP(T11,$B$3:$R$2338,14,0) -> 650 | AH11: =VLOOKUP(T11,$B$3:$R$2338,15,0) -> tier - 3 | AI11: =VLOOKUP(T11,B10:R2345,16,0) -> tier - 3 | AJ11: =VLOOKUP(T11,$B$3:$R$2338,17,0) -> R1013
B12: Id9 | C12: Patrick R | D12: 41.14 | E12: =IF(D12<18.5,"Underweight", IF(AND(D12>=18.5,D12<=24.9),"Healthy Weight", IF(AND(D12>=25,D12<=29.9),"Overweight", IF(D12>=30,"Obesity")))) -> Obesity | F12: 9.58 | G12: =IF(F12<5.7,"Normal",IF(AND(F12>=5.7,F12<=6.4),"Prediabetes",IF(F12>=6.5,"Diabetes"))) -> Diabetes | H12: Yes | I12: No | J12: Yes | K12: 1 | L12: Yes | M12: 29-Nov-2002 | N12: 21 | O12: 668 | P12: tier - 3 | Q12: tier - 2 | R12: R1012 | T12: Id9 | U12: =VLOOKUP(T12,$B$3:$R$2338,2,FALSE) -> Patrick R | V12: =VLOOKUP(T12,$B$3:$R$2338,3,FALSE) -> 41.14 | W12: =VLOOKUP(T12,$B$3:$R$2338,4,FALSE) -> Obesity | X12: =VLOOKUP(T12,$B$3:$R$2338,5,FALSE) -> 9.58 | Y12: =VLOOKUP(T12,$B$3:$R$2338,6,0) -> Diabetes | Z12: =VLOOKUP(T12,$B$3:$R$2338,7,0) -> Yes | AA12: =VLOOKUP(T12,$B$3:$R$2338,8,0) -> No | AB12: =VLOOKUP(T12,$B$3:$R$2338,9,0) -> Yes | AC12: =VLOOKUP(T12,$B$3:$R$2338,10,0) -> 1 | AD12: =VLOOKUP(T12,$B$3:$R$2338,11,0) -> Yes | AE12: =VLOOKUP(T12,$B$3:$R$2338,12,0) -> 29-Nov-2002 | AF12: =VLOOKUP(T12,$B$3:$R$2338,13,0) -> 21 | AG12: =VLOOKUP(T12,$B$3:$R$2338,14,0) -> 668 | AH12: =VLOOKUP(T12,$B$3:$R$2338,15,0) -> tier - 3 | AI12: =VLOOKUP(T12,B11:R2346,16,0) -> tier - 2 | AJ12: =VLOOKUP(T12,$B$3:$R$2338,17,0) -> R1012
B13: Id10 | C13: Brooke N | D13: 38.06 | E13: =IF(D13<18.5,"Underweight", IF(AND(D13>=18.5,D13<=24.9),"Healthy Weight", IF(AND(D13>=25,D13<=29.9),"Overweight", IF(D13>=30,"Obesity")))) -> Obesity | F13: 10.79 | G13: =IF(F13<5.7,"Normal",IF(AND(F13>=5.7,F13<=6.4),"Prediabetes",IF(F13>=6.5,"Diabetes"))) -> Diabetes | H13: No | I13: No | J13: No | K13: No major surgery | L13: Yes | M13: 9-Nov-1997 | N13: 26 | O13: 670 | P13: tier - 3 | Q13: tier - 3 | R13: R1013 | T13: Id10 | U13: =VLOOKUP(T13,$B$3:$R$2338,2,FALSE) -> Brooke N | V13: =VLOOKUP(T13,$B$3:$R$2338,3,FALSE) -> 38.06 | W13: =VLOOKUP(T13,$B$3:$R$2338,4,FALSE) -> Obesity | X13: =VLOOKUP(T13,$B$3:$R$2338,5,FALSE) -> 10.79 | Y13: =VLOOKUP(T13,$B$3:$R$2338,6,0) -> Diabetes | Z13: =VLOOKUP(T13,$B$3:$R$2338,7,0) -> No | AA13: =VLOOKUP(T13,$B$3:$R$2338,8,0) -> No | AB13: =VLOOKUP(T13,$B$3:$R$2338,9,0) -> No | AC13: =VLOOKUP(T13,$B$3:$R$2338,10,0) -> No major surgery | AD13: =VLOOKUP(T13,$B$3:$R$2338,11,0) -> Yes | AE13: =VLOOKUP(T13,$B$3:$R$2338,12,0) -> 9-Nov-1997 | AF13: =VLOOKUP(T13,$B$3:$R$2338,13,0) -> 26 | AG13: =VLOOKUP(T13,$B$3:$R$2338,14,0) -> 670 | AH13: =VLOOKUP(T13,$B$3:$R$2338,15,0) -> tier - 3 | AI13: =VLOOKUP(T13,B12:R2347,16,0) -> tier - 3 | AJ13: =VLOOKUP(T13,$B$3:$R$2338,17,0) -> R1013
B14: Id11 | C14: Paola Andrea | D14: 37.7 | E14: =IF(D14<18.5,"Underweight", IF(AND(D14>=18.5,D14<=24.9),"Healthy Weight", IF(AND(D14>=25,D14<=29.9),"Overweight", IF(D14>=30,"Obesity")))) -> Obesity | F14: 5.96 | G14: =IF(F14<5.7,"Normal",IF(AND(F14>=5.7,F14<=6.4),"Prediabetes",IF(F14>=6.5,"Diabetes"))) -> Prediabetes | H14: Yes | I14: No | J14: No | K14: 2 | L14: Yes | M14: 12-Sep-2001 | N14: 22 | O14: 687.54 | P14: tier - 3 | Q14: tier - 2 | R14: R1013 | T14: Id11 | U14: =VLOOKUP(T14,$B$3:$R$2338,2,FALSE) -> Paola Andrea | V14: =VLOOKUP(T14,$B$3:$R$2338,3,FALSE) -> 37.7 | W14: =VLOOKUP(T14,$B$3:$R$2338,4,FALSE) -> Obesity | X14: =VLOOKUP(T14,$B$3:$R$2338,5,FALSE) -> 5.96 | Y14: =VLOOKUP(T14,$B$3:$R$2338,6,0) -> Prediabetes | Z14: =VLOOKUP(T14,$B$3:$R$2338,7,0) -> Yes | AA14: =VLOOKUP(T14,$B$3:$R$2338,8,0) -> No | AB14: =VLOOKUP(T14,$B$3:$R$2338,9,0) -> No | AC14: =VLOOKUP(T14,$B$3:$R$2338,10,0) -> 2 | AD14: =VLOOKUP(T14,$B$3:$R$2338,11,0) -> Yes | AE14: =VLOOKUP(T14,$B$3:$R$2338,12,0) -> 12-Sep-2001 | AF14: =VLOOKUP(T14,$B$3:$R$2338,13,0) -> 22 | AG14: =VLOOKUP(T14,$B$3:$R$2338,14,0) -> 687.54 | AH14: =VLOOKUP(T14,$B$3:$R$2338,15,0) -> tier - 3 | AI14: =VLOOKUP(T14,B13:R2348,16,0) -> tier - 2 | AJ14: =VLOOKUP(T14,$B$3:$R$2338,17,0) -> R1013
B15: Id12 | C15: David | D15: 42.13 | E15: =IF(D15<18.5,"Underweight", IF(AND(D15>=18.5,D15<=24.9),"Healthy Weight", IF(AND(D15>=25,D15<=29.9),"Overweight", IF(D15>=30,"Obesity")))) -> Obesity | F15: 11.9 | G15: =IF(F15<5.7,"Normal",IF(AND(F15>=5.7,F15<=6.4),"Prediabetes",IF(F15>=6.5,"Diabetes"))) -> Diabetes | H15: No | I15: No | J15: No | K15: No major surgery | L15: Yes | M15: 26-Dec-1999 | N15: 24 | O15: 700 | P15: ? | Q15: tier - 3 | R15: R1013 | T15: Id12 | U15: =VLOOKUP(T15,$B$3:$R$2338,2,FALSE) -> David | V15: =VLOOKUP(T15,$B$3:$R$2338,3,FALSE) -> 42.13 | W15: =VLOOKUP(T15,$B$3:$R$2338,4,FALSE) -> Obesity | X15: =VLOOKUP(T15,$B$3:$R$2338,5,FALSE) -> 11.9 | Y15: =VLOOKUP(T15,$B$3:$R$2338,6,0) -> Diabetes | Z15: =VLOOKUP(T15,$B$3:$R$2338,7,0) -> No | AA15: =VLOOKUP(T15,$B$3:$R$2338,8,0) -> No | AB15: =VLOOKUP(T15,$B$3:$R$2338,9,0) -> No | AC15: =VLOOKUP(T15,$B$3:$R$2338,10,0) -> No major surgery | AD15: =VLOOKUP(T15,$B$3:$R$2338,11,0) -> Yes | AE15: =VLOOKUP(T15,$B$3:$R$2338,12,0) -> 26-Dec-1999 | AF15: =VLOOKUP(T15,$B$3:$R$2338,13,0) -> 24 | AG15: =VLOOKUP(T15,$B$3:$R$2338,14,0) -> 700 | AH15: =VLOOKUP(T15,$B$3:$R$2338,15,0) -> ? | AI15: =VLOOKUP(T15,B14:R2349,16,0) -> tier - 3 | AJ15: =VLOOKUP(T15,$B$3:$R$2338,17,0) -> R1013
B16: Id13 | C16: Wade | D16: 40.92 | E16: =IF(D16<18.5,"Underweight", IF(AND(D16>=18.5,D16<=24.9),"Healthy Weight", IF(AND(D16>=25,D16<=29.9),"Overweight", IF(D16>=30,"Obesity")))) -> Obesity | F16: 8.41 | G16: =IF(F16<5.7,"Normal",IF(AND(F16>=5.7,F16<=6.4),"Prediabetes",IF(F16>=6.5,"Diabetes"))) -> Diabetes | H16: No | I16: No | J16: No | K16: No major surgery | L16: Yes | M16: 14-Dec-1999 | N16: 24 | O16: 722.99 | P16: tier - 3 | Q16: tier - 1 | R16: R1013 | T16: Id13 | U16: =VLOOKUP(T16,$B$3:$R$2338,2,FALSE) -> Wade | V16: =VLOOKUP(T16,$B$3:$R$2338,3,FALSE) -> 40.92 | W16: =VLOOKUP(T16,$B$3:$R$2338,4,FALSE) -> Obesity | X16: =VLOOKUP(T16,$B$3:$R$2338,5,FALSE) -> 8.41 | Y16: =VLOOKUP(T16,$B$3:$R$2338,6,0) -> Diabetes | Z16: =VLOOKUP(T16,$B$3:$R$2338,7,0) -> No | AA16: =VLOOKUP(T16,$B$3:$R$2338,8,0) -> No | AB16: =VLOOKUP(T16,$B$3:$R$2338,9,0) -> No | AC16: =VLOOKUP(T16,$B$3:$R$2338,10,0) -> No major surgery | AD16: =VLOOKUP(T16,$B$3:$R$2338,11,0) -> Yes | AE16: =VLOOKUP(T16,$B$3:$R$2338,12,0) -> 14-Dec-1999 | AF16: =VLOOKUP(T16,$B$3:$R$2338,13,0) -> 24 | AG16: =VLOOKUP(T16,$B$3:$R$2338,14,0) -> 722.99 | AH16: =VLOOKUP(T16,$B$3:$R$2338,15,0) -> tier - 3 | AI16: =VLOOKUP(T16,B15:R2350,16,0) -> tier - 1 | AJ16: =VLOOKUP(T16,$B$3:$R$2338,17,0) -> R1013
B17: Id14 | C17: Franklin | D17: 40.565 | E17: =IF(D17<18.5,"Underweight", IF(AND(D17>=18.5,D17<=24.9),"Healthy Weight", IF(AND(D17>=25,D17<=29.9),"Overweight", IF(D17>=30,"Obesity")))) -> Obesity | F17: 7.02 | G17: =IF(F17<5.7,"Normal",IF(AND(F17>=5.7,F17<=6.4),"Prediabetes",IF(F17>=6.5,"Diabetes"))) -> Diabetes | H17: No | I17: No | J17: No | K17: No major surgery | L17: Yes | M17: 19-Sep-2002 | N17: 21 | O17: 750 | P17: tier - 3 | Q17: tier - 1 | R17: R1012 | T17: Id14 | U17: =VLOOKUP(T17,$B$3:$R$2338,2,FALSE) -> Franklin | V17: =VLOOKUP(T17,$B$3:$R$2338,3,FALSE) -> 40.565 | W17: =VLOOKUP(T17,$B$3:$R$2338,4,FALSE) -> Obesity | X17: =VLOOKUP(T17,$B$3:$R$2338,5,FALSE) -> 7.02 | Y17: =VLOOKUP(T17,$B$3:$R$2338,6,0) -> Diabetes | Z17: =VLOOKUP(T17,$B$3:$R$2338,7,0) -> No | AA17: =VLOOKUP(T17,$B$3:$R$2338,8,0) -> No | AB17: =VLOOKUP(T17,$B$3:$R$2338,9,0) -> No | AC17: =VLOOKUP(T17,$B$3:$R$2338,10,0) -> No major surgery | AD17: =VLOOKUP(T17,$B$3:$R$2338,11,0) -> Yes | AE17: =VLOOKUP(T17,$B$3:$R$2338,12,0) -> 19-Sep-2002 | AF17: =VLOOKUP(T17,$B$3:$R$2338,13,0) -> 21 | AG17: =VLOOKUP(T17,$B$3:$R$2338,14,0) -> 750 | AH17: =VLOOKUP(T17,$B$3:$R$2338,15,0) -> tier - 3 | AI17: =VLOOKUP(T17,B16:R2351,16,0) -> tier - 1 | AJ17: =VLOOKUP(T17,$B$3:$R$2338,17,0) -> R1012
B18: Id15 | C18: Leilani M | D18: 36.385 | E18: =IF(D18<18.5,"Underweight", IF(AND(D18>=18.5,D18<=24.9),"Healthy Weight", IF(AND(D18>=25,D18<=29.9),"Overweight", IF(D18>=30,"Obesity")))) -> Obesity | F18: 7.59 | G18: =IF(F18<5.7,"Normal",IF(AND(F18>=5.7,F18<=6.4),"Prediabetes",IF(F18>=6.5,"Diabetes"))) -> Diabetes | H18: Yes | I18: No | J18: No | K18: 2 | L18: Yes | M18: 9-Aug-1993 | N18: 30 | O18: 760 | P18: tier - 3 | Q18: tier - 1 | R18: R1013 | T18: Id15 | U18: =VLOOKUP(T18,$B$3:$R$2338,2,FALSE) -> Leilani M | V18: =VLOOKUP(T18,$B$3:$R$2338,3,FALSE) -> 36.385 | W18: =VLOOKUP(T18,$B$3:$R$2338,4,FALSE) -> Obesity | X18: =VLOOKUP(T18,$B$3:$R$2338,5,FALSE) -> 7.59 | Y18: =VLOOKUP(T18,$B$3:$R$2338,6,0) -> Diabetes | Z18: =VLOOKUP(T18,$B$3:$R$2338,7,0) -> Yes | AA18: =VLOOKUP(T18,$B$3:$R$2338,8,0) -> No | AB18: =VLOOKUP(T18,$B$3:$R$2338,9,0) -> No | AC18: =VLOOKUP(T18,$B$3:$R$2338,10,0) -> 2 | AD18: =VLOOKUP(T18,$B$3:$R$2338,11,0) -> Yes | AE18: =VLOOKUP(T18,$B$3:$R$2338,12,0) -> 9-Aug-1993 | AF18: =VLOOKUP(T18,$B$3:$R$2338,13,0) -> 30 | AG18: =VLOOKUP(T18,$B$3:$R$2338,14,0) -> 760 | AH18: =VLOOKUP(T18,$B$3:$R$2338,15,0) -> tier - 3 | AI18: =VLOOKUP(T18,B17:R2352,16,0) -> tier - 1 | AJ18: =VLOOKUP(T18,$B$3:$R$2338,17,0) -> R1013
B19: Id16 | C19: Philippe | D19: 39.9 | E19: =IF(D19<18.5,"Underweight", IF(AND(D19>=18.5,D19<=24.9),"Healthy Weight", IF(AND(D19>=25,D19<=29.9),"Overweight", IF(D19>=30,"Obesity")))) -> Obesity | F19: 11.32 | G19: =IF(F19<5.7,"Normal",IF(AND(F19>=5.7,F19<=6.4),"Prediabetes",IF(F19>=6.5,"Diabetes"))) -> Diabetes | H19: No | I19: No | J19: No | K19: No major surgery | L19: Yes | M19: 22-Oct-1996 | N19: 27 | O19: 760 | P19: tier - 3 | Q19: tier - 3 | R19: R1013 | T19: Id16 | U19: =VLOOKUP(T19,$B$3:$R$2338,2,FALSE) -> Philippe | V19: =VLOOKUP(T19,$B$3:$R$2338,3,FALSE) -> 39.9 | W19: =VLOOKUP(T19,$B$3:$R$2338,4,FALSE) -> Obesity | X19: =VLOOKUP(T19,$B$3:$R$2338,5,FALSE) -> 11.32 | Y19: =VLOOKUP(T19,$B$3:$R$2338,6,0) -> Diabetes | Z19: =VLOOKUP(T19,$B$3:$R$2338,7,0) -> No | AA19: =VLOOKUP(T19,$B$3:$R$2338,8,0) -> No | AB19: =VLOOKUP(T19,$B$3:$R$2338,9,0) -> No | AC19: =VLOOKUP(T19,$B$3:$R$2338,10,0) -> No major surgery | AD19: =VLOOKUP(T19,$B$3:$R$2338,11,0) -> Yes | AE19: =VLOOKUP(T19,$B$3:$R$2338,12,0) -> 22-Oct-1996 | AF19: =VLOOKUP(T19,$B$3:$R$2338,13,0) -> 27 | AG19: =VLOOKUP(T19,$B$3:$R$2338,14,0) -> 760 | AH19: =VLOOKUP(T19,$B$3:$R$2338,15,0) -> tier - 3 | AI19: =VLOOKUP(T19,B18:R2353,16,0) -> tier - 3 | AJ19: =VLOOKUP(T19,$B$3:$R$2338,17,0) -> R1013
B20: Id17 | C20: Jennifer A | D20: 33.8 | E20: =IF(D20<18.5,"Underweight", IF(AND(D20>=18.5,D20<=24.9),"Healthy Weight", IF(AND(D20>=25,D20<=29.9),"Overweight", IF(D20>=30,"Obesity")))) -> Obesity | F20: 7.67 | G20: =IF(F20<5.7,"Normal",IF(AND(F20>=5.7,F20<=6.4),"Prediabetes",IF(F20>=6.5,"Diabetes"))) -> Diabetes | H20: No | I20: No | J20: No | K20: 3 | L20: Yes | M20: 28-Jun-1993 | N20: 30 | O20: 770 | P20: tier - 3 | Q20: tier - 3 | R20: R1013 | T20: Id17 | U20: =VLOOKUP(T20,$B$3:$R$2338,2,FALSE) -> Jennifer A | V20: =VLOOKUP(T20,$B$3:$R$2338,3,FALSE) -> 33.8 | W20: =VLOOKUP(T20,$B$3:$R$2338,4,FALSE) -> Obesity | X20: =VLOOKUP(T20,$B$3:$R$2338,5,FALSE) -> 7.67 | Y20: =VLOOKUP(T20,$B$3:$R$2338,6,0) -> Diabetes | Z20: =VLOOKUP(T20,$B$3:$R$2338,7,0) -> No | AA20: =VLOOKUP(T20,$B$3:$R$2338,8,0) -> No | AB20: =VLOOKUP(T20,$B$3:$R$2338,9,0) -> No | AC20: =VLOOKUP(T20,$B$3:$R$2338,10,0) -> 3 | AD20: =VLOOKUP(T20,$B$3:$R$2338,11,0) -> Yes | AE20: =VLOOKUP(T20,$B$3:$R$2338,12,0) -> 28-Jun-1993 | AF20: =VLOOKUP(T20,$B$3:$R$2338,13,0) -> 30 | AG20: =VLOOKUP(T20,$B$3:$R$2338,14,0) -> 770 | AH20: =VLOOKUP(T20,$B$3:$R$2338,15,0) -> tier - 3 | AI20: =VLOOKUP(T20,B19:R2354,16,0) -> tier - 3 | AJ20: =VLOOKUP(T20,$B$3:$R$2338,17,0) -> R1013
B21: Id18 | C21: Christina M | D21: 36.765 | E21: =IF(D21<18.5,"Underweight", IF(AND(D21>=18.5,D21<=24.9),"Healthy Weight", IF(AND(D21>=25,D21<=29.9),"Overweight", IF(D21>=30,"Obesity")))) -> Obesity | F21: 7.29 | G21: =IF(F21<5.7,"Normal",IF(AND(F21>=5.7,F21<=6.4),"Prediabetes",IF(F21>=6.5,"Diabetes"))) -> Diabetes | H21: Yes | I21: No | J21: Yes | K21: 1 | L21: Yes | M21: 18-Sep-1996 | N21: 27 | O21: 770.38 | P21: tier - 3 | Q21: ? | R21: R1012 | T21: Id18 | U21: =VLOOKUP(T21,$B$3:$R$2338,2,FALSE) -> Christina M | V21: =VLOOKUP(T21,$B$3:$R$2338,3,FALSE) -> 36.765 | W21: =VLOOKUP(T21,$B$3:$R$2338,4,FALSE) -> Obesity | X21: =VLOOKUP(T21,$B$3:$R$2338,5,FALSE) -> 7.29 | Y21: =VLOOKUP(T21,$B$3:$R$2338,6,0) -> Diabetes | Z21: =VLOOKUP(T21,$B$3:$R$2338,7,0) -> Yes | AA21: =VLOOKUP(T21,$B$3:$R$2338,8,0) -> No | AB21: =VLOOKUP(T21,$B$3:$R$2338,9,0) -> Yes | AC21: =VLOOKUP(T21,$B$3:$R$2338,10,0) -> 1 | AD21: =VLOOKUP(T21,$B$3:$R$2338,11,0) -> Yes | AE21: =VLOOKUP(T21,$B$3:$R$2338,12,0) -> 18-Sep-1996 | AF21: =VLOOKUP(T21,$B$3:$R$2338,13,0) -> 27 | AG21: =VLOOKUP(T21,$B$3:$R$2338,14,0) -> 770.38 | AH21: =VLOOKUP(T21,$B$3:$R$2338,15,0) -> tier - 3 | AI21: =VLOOKUP(T21,B20:R2355,16,0) -> ? | AJ21: =VLOOKUP(T21,$B$3:$R$2338,17,0) -> R1012
